Workbook

Sheet README
A1: Techno-economic and life-cycle (energy/GHG) assessment: Memb-Integration-1
A2: Biogas (anaerobic digestion) -> zeolite membrane upgrading -> catalytic methane pyrolysis to hydrogen and solid carbon. All costs in USD.
A4: PURPOSE
A5: Screening-level TEA and gate-to-gate energy/GHG assessment of the current Aspen Plus model, using the method of the two reference papers in TEA/LCA-ref-docs.
A6: Main outputs (sheet Summary): total project investment, annual operating cost, levelised cost of hydrogen (LCOH), net energy ratio (NER), GHG intensity.
A8: HOW TO USE / COLOUR LEGEND
A9: Blue text = hardcoded input (edit these). Black text = formula. Green text = link to another sheet.
A10: Yellow fill = key assumption or estimate that should be checked or replaced (especially the equipment costs on sheet CAPEX).
A11: Edit only blue cells. Every input has its source in the column next to it or in a cell comment.
A13: SHEETS
A14: Process_Data: mass flows and energy duties from the latest Aspen run (2026-10-06).
A15: Assumptions: economic method, prices and LCA factors, with sources.
... A48: [12] Chemical Engineering magazine CEPCI (2014 annual 576.1; 2024 monthly about 795-800). ECB 2024 average 1.0824 USD/EUR.

Sheet Summary
A1: Summary: TEA and LCA of the current process (USD)
A2: Screening estimate. Equipment costs are indicative (see CAPEX); process data from the Aspen run of 2026-10-06.
A4: Result | B4: Value | C4: Unit | D4: Note
A5: Hydrogen production (steady state) | B5: =OPEX!$B$30/1000 | C5: t/yr | D5: 85 % capacity factor
A6: Solid carbon by-product | B6: =OPEX!$B$27 | C6: t/yr
A7: Turnkey items (AD plant + upgrading), installed | B7: =CAPEX!$F$14 | C7: USD | D7: IEA Bioenergy cost data
A8: Purchased equipment (pyrolysis section, membrane premium) | B8: =CAPEX!$F$16 | C8: USD | D8: Textbook correlations + factors of [1], [2]
A9: Total project investment (TPI) | B9: =CAPEX!$F$23 | C9: USD | D9: TPEC x factors of [1], [2]
A10: Annual operating cost (steady state) | B10: =OPEX!$D$24 | C10: USD/yr
A11: Annual by-product credits | B11: =OPEX!$D$29 | C11: USD/yr | D11: Solid carbon (+ digestate if valued)
A12: Levelised cost of hydrogen (DCF, 10 % IRR) | B12: =DCF!$B$26 | C12: USD/kg H2 | D12: First-year price escalating 5 %/yr ([1], [2] method)
A13: Capital recovery factor | B13: =(Assumptions!$B$10*(1+Assumptions!$B$10)^Assumptions!$B$9/((1+Assumptions!$B$10)^Assumptions!$B$9-1)) | C13: - | D13: Constant-dollar cross-check
A14: LCOH, simple constant-dollar (CRF x TPI + OPEX - credits) / H2 | B14: =(B13*B9+B10-B11)/OPEX!$B$30 | C14: USD/kg H2 | D14: No escalation, no construction period
A15: Net energy ratio (NER) | B15: =LCA!$B$12 | C15: - | D15: [1] definition
A16: GHG intensity (gate-to-gate) | B16: =LCA!$B$20 | C16: kg CO2e/kg H2 | D16: Carbon-storage credit per switch on Assumptions
A18: Annual cost breakdown (steady state)
A19: Component | B19: USD/yr | C19: Share
A20: Capital (CRF x TPI) | B20: =B13*B9 | C20: =B20/B$28
A21: Utilities | B21: =OPEX!$D$10 | C21: =B21/B$28
A22: Raw materials (water, feed, catalyst, membrane) | B22: =OPEX!$D$16 | C22: =B22/B$28
A23: Operating labour | B23: =OPEX!$D$18 | C23: =B23/B$28
A24: Maintenance | B24: =OPEX!$D$19 | C24: =B24/B$28
A25: Operating charges + plant overhead | B25: =OPEX!$D$21+OPEX!$D$22 | C25: =B25/B$28
A26: General & administrative | B26: =OPEX!$D$23 | C26: =B26/B$28
A27: By-product credits (negative) | B27: =-B11 | C27: =B27/B$28
A28: Total annual net cost | B28: =SUM(B20:B27) | C28: =SUM(C20:C27)
A29: Check: total / H2 = simple LCOH | B29: =B28/OPEX!$B$30
A31: One-at-a-time sensitivity of the simple LCOH (USD/kg H2)
A32: Case | B32: LCOH (USD/kg) | C32: Change vs base | D32: How it is computed
A33: Base case | B33: =B14 | C33: =B33/B14-1 | D33: Base
A34: Capital (TPI) -30 % | B34: =B14+(-0.3*B13*B9-0.3*OPEX!$D$19*(1+Assumptions!$B$28+Assumptions!$B$29))/OPEX!$B$30 | C34: =B34/B14-1 | D34: Capital term, maintenance and its overhead/G&A scale with TPI
A35: Capital (TPI) +30 % | B35: =B14+(0.3*B13*B9+0.3*OPEX!$D$19*(1+Assumptions!$B$28+Assumptions!$B$29))/OPEX!$B$30 | C35: =B35/B14-1 | D35: As above
A36: Natural gas price x2 | B36: =B14+(OPEX!$D$7+OPEX!$D$8)*(1+Assumptions!$B$29)/OPEX!$B$30 | C36: =B36/B14-1 | D36: Adds one more year of gas cost (+ G&A)
A37: Electricity price x2 | B37: =B14+OPEX!$D$6*(1+Assumptions!$B$29)/OPEX!$B$30 | C37: =B37/B14-1 | D37: Adds one more year of electricity cost (+ G&A)
A38: Operating labour x0.5 | B38: =B14-0.5*OPEX!$D$18*(1+Assumptions!$B$27+Assumptions!$B$28+Assumptions!$B$29)/OPEX!$B$30 | C38: =B38/B14-1 | D38: Labour with its charges, overhead and G&A
A39: Solid carbon credit 1,200 USD/t (carbon-black price level) | B39: =B14-OPEX!$B$27*(1200-Assumptions!$B$49)/OPEX!$B$30 | C39: =B39/B14-1 | D39: Carbon sold near the 2024 carbon-black price (about 1,040-1,820 $/t)
A40: Upgrading unit cost at IEA Task 37 small-unit level (x2.5) | B40: =B14+1.5*CAPEX!$F$6*(1+Assumptions!$B$65)*(1+Assumptions!$B$23)*(1+Assumptions!$B$24)*(B13+Assumptions!$B$26*(1+Assumptions!$B$28+Assumptions!$B$29))/OPEX!$B$30 | C40: =B40/B14-1 | D40: Small 10-30 m3/h units (233-361 kGBP in 2014) suggest roughly 2.5x the scaled IEA Task 44 value
A41: Zeolite membrane price 5,000 USD/m2 | B41: =B14+Process_Data!$B$12*(5000-Assumptions!$B$44)*((Assumptions!$B$21+Assumptions!$B$22)*(1+Assumptions!$B$23)*(1+Assumptions!$B$24)*(B13+Assumptions!$B$26*(1+Assumptions!$B$28+Assumptions!$B$29))+1/Assumptions!$B$46*(1+Assumptions!$B$29))/OPEX!$B$30 | C41: =B41/B14-1 | D41: Top of the 1,000-5,000 EUR/m2 literature range
A42: Hydrogen output -4.2 % (equilibrium-limited pyrolysis) | B42: =B14/(1-0.042) | C42: =B42/B14-1 | D42: Model H2 is about 4 % above equilibrium

Sheet Process_Data
A1: Process data from the Aspen Plus model (latest run 2026-10-06)
A3: Item | B3: Value | C3: Unit | D3: Source / note
A4: Streams and products
A5: Biomass feed (wet, 75.2 % water) | B5: 354.1667 | C5: kg/h | D5: 8.5 t/d (stream BIOMASS). Aspen Plus run 2026-10-06 (files/Memb-Integration-1.his and .bkp)
A6: Process water (WATERIN) | B6: 541.6667 | C6: kg/h | D6: 13 t/d. Aspen Plus run 2026-10-06 (files/Memb-Integration-1.his and .bkp)
A7: Biogas to upgrading (GAS2C) | B7: 2.26801 | C7: kmol/h | D7: Aspen Plus run 2026-10-06 (files/Memb-Integration-1.his and .bkp)
A8: CH4 mole fraction in biogas | B8: 0.587344 | C8: - | D8: Aspen Plus run 2026-10-06 (files/Memb-Integration-1.his and .bkp)
A9: Biogas volumetric flow | B9: =B7*22.414 | C9: Nm3/h | D9: Formula: kmol/h x 22.414 Nm3/kmol
A10: Methane energy in biogas (LHV) | B10: =B7*B8*802.3/3.6 | C10: kW | D10: Formula: CH4 kmol/h x 802.3 MJ/kmol (Perry Table 2-179, net heat of combustion of methane) / 3.6
A11: Digestate (stream LIQUID) | B11: 823.302 | C11: kg/h | D11: Aspen Plus run 2026-10-06 (files/Memb-Integration-1.his and .bkp) (stored stream result)
A12: Membrane area (MEMB1, parameter A) | B12: 5 | C12: m2 | D12: ACM model files/zeo_real.acmf
A13: Retentate to pyrolysis (RET) | B13: 1.68885 | C13: kmol/h | D13: Aspen Plus run 2026-10-06 (files/Memb-Integration-1.his and .bkp)
A14: CH4 mole fraction in retentate | B14: 0.76431 | C14: - | D14: Aspen Plus run 2026-10-06 (files/Memb-Integration-1.his and .bkp)
A15: Permeate (PER, leaves process) | B15: 0.579162 | C15: kmol/h | D15: Aspen Plus run 2026-10-06 (files/Memb-Integration-1.his and .bkp)
A16: CO2 mole fraction in permeate | B16: 0.922368 | C16: - | D16: Aspen Plus run 2026-10-06 (files/Memb-Integration-1.his and .bkp)
A17: CH4 mole fraction in permeate | B17: 0.071304 | C17: - | D17: Aspen Plus run 2026-10-06 (files/Memb-Integration-1.his and .bkp)
A18: Hydrogen in pyrolysis product (FINPROD) | B18: 2.19068 | C18: kmol/h | D18: Aspen Plus run 2026-10-06 (files/Memb-Integration-1.his and .bkp) (stored stream result). Model is about 4 % above equilibrium (see README).
A19: Hydrogen mass flow | B19: =B18*2.01588 | C19: kg/h | D19: Formula: kmol/h x 2.01588 kg/kmol
A20: Methane converted = solid carbon formed | B20: 1.2908 | C20: kmol/h | D20: Aspen Plus run 2026-10-06 (files/Memb-Integration-1.his and .bkp) (CH4 in PYROIN 1.2908 kmol/h, about 100 % converted)
A21: Solid carbon mass flow | B21: =B20*12.011 | C21: kg/h | D21: Formula: kmol/h x 12.011 kg/kmol
A22: CO in pyrolysis product (from RWGS) | B22: 0.394475 | C22: kmol/h | D22: Aspen Plus run 2026-10-06 (files/Memb-Integration-1.his and .bkp)
A23: Pyrolysis catalyst charge | B23: 24.668 | C23: kg | D23: Block CH4PYRO input
A24: Energy (kW; positive = heat or power in)
A25: COMP1 compressor power | B25: 2.71 | C25: kW | D25: Aspen Plus run 2026-10-06 (files/Memb-Integration-1.his and .bkp) (indicated 2710 W)
A26: COMP2 compressor power | B26: 2.758 | C26: kW | D26: Aspen Plus run 2026-10-06 (files/Memb-Integration-1.his and .bkp) (indicated 2758 W)
A27: RSTOIC heating (feed to 55 C + hydrolysis) | B27: 25.036 | C27: kW | D27: Aspen Plus run 2026-10-06 (files/Memb-Integration-1.his and .bkp) (Q = 25036.2 W)
A28: B1 digester heating | B28: 3.428 | C28: kW | D28: Aspen Plus run 2026-10-06 (files/Memb-Integration-1.his and .bkp) (reactor duty 3428.46 W)
A29: HEAT2 heating 30 -> 790 C | B29: 19.385 | C29: kW | D29: Aspen Plus run 2026-10-06 (files/Memb-Integration-1.his and .bkp) (Q = 19385.3 W; Perry Cp check gives 19.44 kW)
A30: Reaction enthalpy CH4 -> C + 2H2 at 790 C | B30: 89.63 | C30: MJ/kmol | D30: Computed from Perry Handbook data (Cp Table 2-156, dHf Table 2-179, graphite Cp Table 2-151)
A31: Reaction enthalpy CO2 + H2 -> CO + H2O at 790 C | B31: 34.2 | C31: MJ/kmol | D31: Same method as above
A32: CH4PYRO reactor heat (estimate) | B32: =(B20*B30+B22*B31)/3.6 | C32: kW | D32: ESTIMATE: Aspen does not print the RPLUG duty. Formula = extents x reaction enthalpies (isothermal 790 C). Read the real duty from Aspen on Windows.
A33: FLASH cooling (biogas to 25 C) | B33: 5.297 | C33: kW | D33: Aspen Plus run 2026-10-06 (files/Memb-Integration-1.his and .bkp) (Q = -5297.34 W)
A34: COOL1 cooling | B34: 2.596 | C34: kW | D34: Aspen Plus run 2026-10-06 (files/Memb-Integration-1.his and .bkp) (Q = -2595.69 W)
A35: COOL2 cooling | B35: 2.758 | C35: kW | D35: Aspen Plus run 2026-10-06 (files/Memb-Integration-1.his and .bkp) (Q = -2758.40 W)
A36: Total cooling duty | B36: =B33+B34+B35 | C36: kW | D36: Formula. Pyrolysis product cooling is not modelled.

Sheet Assumptions
A1: Assumptions (all costs in USD)
A3: Parameter | B3: Value | C3: Unit | D3: Source / note
A4: Economic method (reference papers)
A5: Calendar hours per year | B5: 8760 | C5: h/yr | D5: Definition
A6: Capacity factor, steady state (year 3+) | B6: 0.85 | C6: - | D6: Plant start-up factor Year 2+ = 0.85 [1] Table 5, [2] Table 6
A7: Start-up factor, operating year 1 | B7: 0.7 | C7: - | D7: [1] Table 5, [2] Table 6
A8: Start-up factor, operating year 2 | B8: 0.8 | C8: - | D8: [1] Table 5, [2] Table 6
A9: Plant life | B9: 20 | C9: yr | D9: [1] Table 5, [2] Table 6
A10: IRR / discount rate | B10: 0.1 | C10: - | D10: [1] Table 5, [2] Table 6
A11: Construction spend, year -3 | B11: 0.2 | C11: - | D11: [2] Table 6 (spread of construction cost)
A12: Construction spend, year -2 | B12: 0.35 | C12: - | D12: [2] Table 6
A13: Construction spend, year -1 | B13: 0.45 | C13: - | D13: [2] Table 6 (remainder; [1] text lists 20/45/35 %, the table order is ambiguous in the PDF)
A14: Escalation: project capital | B14: 0.05 | C14: - | D14: [2] Table 6
A15: Escalation: products (H2, by-products) | B15: 0.05 | C15: - | D15: [1] Table 5, [2] Table 6
A16: Escalation: raw materials | B16: 0.035 | C16: - | D16: [1] Table 5, [2] Table 6
... A19: Escalation: general & administrative | B19: 0.035 | C19: - | D19: [1] Table 5, [2] Table 6
A20: Capital-cost factors (Peters & Timmerhaus, as used in [1] Table 4, [2] Table 5)
A21: Total installed cost (TIC), x TPEC | B21: 3.02 | C21: - | D21: [1] Table 4, [2] Table 5: TIC = 302 % TPEC
A22: Indirect cost (IC), x TPEC | B22: 0.89 | C22: - | D22: [1] Table 4, [2] Table 5: IC = 89 % TPEC
A23: Contingency, x (TIC + IC) | B23: 0.2 | C23: - | D23: [1] Table 4, [2] Table 5
A24: Location factor, x FCI | B24: 0.1 | C24: - | D24: [1] Table 4, [2] Table 5
A25: Operating-cost factors ([1] Table 5)
A26: Maintenance, x TPI | B26: 0.03 | C26: - | D26: [1] Table 5: 3 % of TPI
A27: Operating charges, x labour | B27: 0.25 | C27: - | D27: [1] Table 5
A28: Plant overhead, x (labour + maintenance) | B28: 0.5 | C28: - | D28: [1] Table 5
A29: General & administrative, x total operating cost | B29: 0.08 | C29: - | D29: [1] Table 5
A30: Prices
A31: Electricity price | B31: 0.0813 | C31: $/kWh | D31: US EIA, Electric Power Annual 2024: average industrial price 8.13 c/kWh. (Papers: [1] 0.056, [2] 0.04 $/kWh)
A32: Natural gas price, industrial | B32: 3.93 | C32: $/Mcf | D32: US EIA, Natural Gas Annual 2024: average price delivered to industrial consumers 3.93 $/thousand cubic feet
A33: Natural gas heat content | B33: 1.036 | C33: MMBtu/Mcf | D33: US EIA approximate heat content of natural gas (about 1,036 Btu per cubic foot)
A34: Natural gas price (heating fuel) | B34: =B32/(B33*1.055056) | C34: $/GJ | D34: Formula: $/Mcf / (MMBtu/Mcf x 1.055056 GJ/MMBtu)
A35: Low-temperature heater efficiency (digester heating) | B35: 0.85 | C35: - | D35: ASSUMPTION
A36: High-temperature fired heater efficiency (790 C heating, pyrolysis) | B36: 0.8 | C36: - | D36: ASSUMPTION
A37: Cooling water cost | B37: 0.35 | C37: $/GJ removed | D37: ASSUMPTION
A38: Process water price | B38: 0.5 | C38: $/m3 | D38: ASSUMPTION
A39: Biomass feed cost (wet) | B39: 0 | C39: $/t | D39: ASSUMPTION: organic waste at zero cost. [2] used 48 $/t delivered forest biomass (different feed).
A40: Specific electricity of membrane upgrading (incl. pretreatment) | B40: 0.2 | C40: kWh/Nm3 | D40: IEA Task 44 (2025) p. 24: 0.2-0.38 kWh/Nm3 (lower end used). The model's compressors alone use about 0.11 kWh/Nm3
A41: Digester mixing and pumps allowance | B41: 2 | C41: kW | D41: ASSUMPTION allowance (not in the Aspen model)
A42: Pyrolysis catalyst price | B42: 40 | C42: $/kg | D42: ASSUMPTION
A43: Catalyst charges replaced per year | B43: 1 | C43: 1/yr | D43: ASSUMPTION (carbon deposition deactivates CH4-cracking catalysts)
...

Sheet CAPEX
A1: Capital cost (USD, 2024 basis)
A2: Two kinds of items: TURNKEY (installed) costs from IEA Bioenergy data, and PURCHASED equipment costs from textbook correlations, to which the reference papers' installation and indirect factors are applied.
A4: # | B4: Item | C4: Aspen blocks covered | D4: Cost type | E4: Basis (formula inputs) | F4: Cost 2024 (USD) | G4: Source / note
A5: 1 | B5: Anaerobic digestion plant (feed tank, hydrolysis, digester, digestate storage, heating) | C5: MIX1, RSTOIC, B1 | D5: Turnkey | E5: =TEXT(Process_Data!$B$10*Assumptions!$B$61,"0")&" kWe-equiv. x "&TEXT(Assumptions!$B$59,"#,##0")&" GBP/kWe x (1-CHP share)" | F5: =Process_Data!$B$10*Assumptions!$B$61*Assumptions!$B$59*(1-Assumptions!$B$60)*Assumptions!$B$57*Assumptions!$B$53/Assumptions!$B$54 | G5: IEA Bioenergy Task 37 (2015), Exploring the viability of small scale anaerobic digesters in livestock farming, ISBN 978-1-910154-25-0, section 5.1, Table 9, Appendix A. Median for plants < 250 kWe; CHP share removed; converted at 1.61 $/GBP (Oct 2014) and CEPCI 2014 -> 2024. Plant size expressed in kWe using the biogas methane energy and an assumed 38 % CHP efficiency.
A6: 2 | B6: Biogas upgrading unit: chilling, H2S and moisture removal, 2-stage compression, coolers, membrane (polymer basis) | C6: FLASH, H2S-SEP, NH3SEP, COMP1, COOL1, COMP2, COOL2, MEMB1 | D6: Turnkey | E6: =TEXT(Process_Data!$B$9,"0.0")&" Nm3/h; "&TEXT(Assumptions!$B$62,"#,##0")&" EUR/(Nm3/h) at "&TEXT(Assumptions!$B$63,"0")&" Nm3/h, scaled with exponent "&TEXT(Assumptions!$B$64,"0.0") | F6: =Assumptions!$B$62*Assumptions!$B$63*(Process_Data!$B$9/Assumptions!$B$63)^Assumptions!$B$64*Assumptions!$B$58 | G6: IEA Bioenergy Task 44 (2025), Technologies for Flexible Bioenergy (Updated), p. 24 (biogas upgrading costs). Upper end of 2,500-6,000 EUR per Nm3/h (100-400 Nm3/h), scaled down with the six-tenths rule (Perry Eq. 9-1). Cross-check: IEA Task 37 (2015) quotes 233,000-361,000 GBP for 10-30 m3/h units, i.e. small units can cost more.
A7: 3 | B7: Zeolite membrane premium over polymer membrane | C7: MEMB1 | D7: Purchased | E7: =TEXT(Process_Data!$B$12,"0.0")&" m2 x ("&TEXT(Assumptions!$B$44,"#,##0")&" - "&TEXT(Assumptions!$B$45,"0")&") $/m2" | F7: =Process_Data!$B$12*(Assumptions!$B$44-Assumptions!$B$45) | G7: The IEA upgrading cost assumes polymer membranes; this adds the extra cost of DDR zeolite modules (prices on Assumptions).
A8: 4 | B8: Pyrolysis reactor tube, nickel alloy (2.12 m3) | C8: CH4PYRO | D8: Purchased | E8: ="Turton vertical vessel, V = 2.12 m3, Ni alloy Fm "&TEXT(Assumptions!$B$68,"0.0") | F8: =10^(3.4974+0.4485*LOG10(2.12)+0.1074*LOG10(2.12)^2)*Assumptions!$B$68*Assumptions!$B$53/Assumptions!$B$56 | G8: Turton et al., Analysis, Synthesis and Design of Chemical Processes, 5th ed., Appendix A (2001 basis, CEPCI 394.3), constants as coded in github.com/weepctxb/ChemEngDPpy capex.py: log10 Cp = 3.4974 + 0.4485 log10 V + 0.1074 (log10 V)^2 (V in m3, 0.3-520), times Ni-alloy factor 7.1, CEPCI 2001 -> 2024. Cross-check: a 10 mm Inconel tube of this size costed by shell mass with Towler & Sinnott gives about 128,000 $.
A9: 5 | B9: Cylindrical fired furnace (heats feed to 790 C and supplies reactor heat) | C9: HEAT2, CH4PYRO | D9: Purchased | E9: =TEXT((Process_Data!$B$29+Process_Data!$B$32)/1000,"0.000")&" MW duty" | F9: =(80000+109000*((Process_Data!$B$29+Process_Data!$B$32)/1000)^0.8)*Assumptions!$B$53/Assumptions!$B$55 | G9: Towler & Sinnott (2013), Chemical Engineering Design 2nd ed., Table 7.2 (US Gulf Coast, Jan 2010, CEPCI 532.9) and Table 7.6: cylindrical furnace Ce = 80,000 + 109,000 S^0.8 (S = duty in MW, valid 0.2-60 MW). Our duty (about 0.055 MW) is BELOW the valid range, so this is an extrapolation.
A10: 6 | B10: Pyrolysis catalyst, initial charge | C10: CH4PYRO | D10: Purchased | E10: =TEXT(Process_Data!$B$23,"0.0")&" kg x catalyst price" | F10: =Process_Data!$B$23*Assumptions!$B$42 | G10: Catalyst price is an assumption (Assumptions sheet).
A11: 7 | B11: Solid carbon separation (cyclone + filter) | C11: (FINPROD) | D11: Purchased | E11: ="about 15.5 kg/h carbon" | F11: 30000 | G11: INDICATIVE ESTIMATE: no verified correlation found for this size. Replace with a vendor quote.
A12: 8 | B12: Product gas cooler (790 C to ambient) | C12: (FINPROD) | D12: Purchased | E12: =TEXT(Assumptions!$B$66,"0.0")&" m2 double-pipe exchanger" | F12: =(1900+2500*Assumptions!$B$66)*Assumptions!$B$53/Assumptions!$B$55 | G12: Towler & Sinnott (2013), Chemical Engineering Design 2nd ed., Table 7.2 (US Gulf Coast, Jan 2010, CEPCI 532.9) and Table 7.6: double pipe Ce = 1,900 + 2,500 A (A in m2, 1-80). Area is an assumption.
B14: Turnkey (installed) items, subtotal | F14: =SUMIF(D5:D12,"Turnkey",F5:F12) | G14: Already installed costs
B15: Owner costs on turnkey items | F15: =F14*Assumptions!$B$65 | G15: IEA Task 37 (2015): +10-15 %
B16: Total purchased equipment cost (TPEC), purchased items | F16: =SUMIF(D5:D12,"Purchased",F5:F12) | G16: Purchased-cost items only
B17: Total installed cost of purchased items (TIC) | F17: =F16*Assumptions!$B$21 | G17: TIC = 302 % TPEC ([1] Table 4, [2] Table 5)
B18: Indirect cost of purchased items (IC) | F18: =F16*Assumptions!$B$22 | G18: IC = 89 % TPEC
B19: Total direct and indirect cost (TDIC) | F19: =F14+F15+F17+F18 | G19: Turnkey + owner costs + TIC + IC
B20: Contingency | F20: =F19*Assumptions!$B$23 | G20: 20 % of TDIC
B21: Fixed capital investment (FCI) | F21: =F19+F20 | G21: TDIC + contingency
B22: Location factor | F22: =F21*Assumptions!$B$24 | G22: 10 % of FCI
B23: Total project investment (TPI) | F23: =F21+F22 | G23: FCI + location factor
B24: Share of TPI from turnkey items (sourced from IEA data) | F24: =(F14+F15)*(1+Assumptions!$B$23)*(1+Assumptions!$B$24)/F23 | G24: How much of the investment rests on the IEA cost data
B25: Share of TPI resting on indicative (unsourced) estimates | F25: =F11*(Assumptions!$B$21+Assumptions!$B$22)*(1+Assumptions!$B$23)*(1+Assumptions!$B$24)/F23 | G25: Carbon separation only

Sheet OPEX
A1: Annual operating cost at steady state (year 3+, capacity factor 0.85), USD of the first operating year
A3: Item | B3: Quantity | C3: Unit | D3: Cost (USD/yr) | E3: Basis
A4: Operating hours | B4: =Assumptions!$B$5*Assumptions!$B$6 | C4: h/yr | E4: Calendar hours x capacity factor
A5: Utilities
A6: Electricity (upgrading + digester auxiliaries) | B6: =(MAX(Process_Data!$B$25+Process_Data!$B$26,Assumptions!$B$40*Process_Data!$B$9)+Assumptions!$B$41)*B4 | C6: kWh/yr | D6: =B6*Assumptions!$B$31 | E6: Upgrading: larger of Aspen compressor power and IEA 0.2 kWh/Nm3; plus digester allowance; x hours x price
A7: Natural gas for digester heating | B7: =(Process_Data!$B$27+Process_Data!$B$28)*B4*0.0036/Assumptions!$B$35 | C7: GJ/yr | D7: =B7*Assumptions!$B$34 | E7: (RSTOIC + B1 heat) x hours / efficiency
A8: Natural gas for 790 C heating and pyrolysis | B8: =(Process_Data!$B$29+Process_Data!$B$32)*B4*0.0036/Assumptions!$B$36 | C8: GJ/yr | D8: =B8*Assumptions!$B$34 | E8: (HEAT2 + CH4PYRO heat) x hours / efficiency
A9: Cooling water | B9: =Process_Data!$B$36*B4*0.0036 | C9: GJ/yr | D9: =B9*Assumptions!$B$37 | E9: Total cooling duty x hours x price
A10: Utilities subtotal | D10: =SUM(D6:D9)
A11: Raw materials
A12: Process water | B12: =Process_Data!$B$6*B4/1000 | C12: m3/yr | D12: =B12*Assumptions!$B$38 | E12: WATERIN x hours
A13: Biomass feed (wet) | B13: =Process_Data!$B$5*B4/1000 | C13: t/yr | D13: =B13*Assumptions!$B$39 | E13: BIOMASS x hours x price
A14: Pyrolysis catalyst replacement | B14: =Process_Data!$B$23*Assumptions!$B$43 | C14: kg/yr | D14: =B14*Assumptions!$B$42 | E14: Charge x replacements per year
A15: Membrane replacement (annualised) | B15: =Process_Data!$B$12/Assumptions!$B$46 | C15: m2/yr | D15: =B15*Assumptions!$B$44 | E15: Area / life x price
A16: Raw materials subtotal | D16: =SUM(D12:D15)
A17: Labour and maintenance
A18: Operating labour | B18: =Assumptions!$B$47 | C18: FTE | D18: =B18*Assumptions!$B$48 | E18: FTE x salary
A19: Maintenance | D19: =CAPEX!$F$23*Assumptions!$B$26 | E19: 3 % of TPI ([1] Table 5)
A20: Total operating cost (labour + maintenance + utilities + raw materials) | D20: =D18+D19+D10+D16 | E20: Definition in [1] Table 5
A21: Operating charges | D21: =D18*Assumptions!$B$27 | E21: 25 % of operating labour
A22: Plant overhead | D22: =(D18+D19)*Assumptions!$B$28 | E22: 50 % of labour + maintenance
A23: General & administrative | D23: =D20*Assumptions!$B$29 | E23: 8 % of total operating cost
A24: TOTAL ANNUAL OPERATING COST | D24: =D20+D21+D22+D23
A26: By-product credits and product
A27: Solid carbon sold | B27: =Process_Data!$B$21*B4/1000 | C27: t/yr | D27: =B27*Assumptions!$B$49 | E27: Carbon mass flow x hours x price
A28: Digestate | B28: =Process_Data!$B$11*B4/1000 | C28: t/yr | D28: =B28*Assumptions!$B$50 | E28: LIQUID x hours x price
A29: Total by-product credits | D29: =D27+D28
A30: Hydrogen produced | B30: =Process_Data!$B$19*B4 | C30: kg/yr | E30: H2 mass flow x hours
A31: Net annual cost (operating cost - credits) | D31: =D24-D29

Sheet DCF
A1: Discounted cash flow: levelised cost of hydrogen at the IRR (method of [1], [2])
A2: Year 1-3 construction, year 4-23 operation. Costs escalate by category; LCOH is the first-year H2 price (escalating at the product rate) that gives NPV = 0 at the IRR.
A4: Year | B4: 1 | C4: 2 | D4: 3 | E4: 4 | F4: 5 | G4: 6 | H4: 7 | I4: 8 | J4: 9 | K4: 10 | L4: 11 | M4: 12 | N4: 13 | O4: 14 | P4: 15 | Q4: 16 | R4: 17 | S4: 18 | T4: 19 | U4: 20 | V4: 21 | W4: 22 | X4: 23
A5: Phase | B5: Construction | C5: Construction | D5: Construction | E5: Operation | F5: Operation | G5: Operation | H5: Operation | I5: Operation | J5: Operation | K5: Operation | L5: Operation | M5: Operation | N5: Operation | O5: Operation | P5: Operation | Q5: Operation | R5: Operation | S5: Operation | T5: Operation | U5: Operation | V5: Operation | W5: Operation | X5: Operation
A6: Operating year # | B6: =MAX(0,B4-3) | C6: =MAX(0,C4-3) | D6: =MAX(0,D4-3) | E6: =MAX(0,E4-3) | F6: =MAX(0,F4-3) | G6: =MAX(0,G4-3) | H6: =MAX(0,H4-3) | I6: =MAX(0,I4-3) | ... X6: =MAX(0,X4-3)
A7: Construction share | B7: =Assumptions!$B$11 | C7: =Assumptions!$B$12 | D7: =Assumptions!$B$13 | E7: 0 | F7: 0 | G7: 0 | H7: 0 | I7: 0 | J7: 0 | K7: 0 | L7: 0 | M7: 0 | N7: 0 | O7: 0 | P7: 0 | Q7: 0 | R7: 0 | S7: 0 | T7: 0 | U7: 0 | V7: 0 | W7: 0 | X7: 0
A8: Capacity factor | B8: =IF(B6=0,0,IF(B6=1,Assumptions!$B$7,IF(B6=2,Assumptions!$B$8,Assumptions!$B$6))) | C8: =IF(C6=0,0,IF(C6=1,Assumptions!$B$7,IF(C6=2,Assumptions!$B$8,Assumptions!$B$6))) | D8: =IF(D6=0,0,IF(D6=1,Assumptions!$B$7,IF(D6=2,Assumptions!$B$8,Assumptions!$B$6))) | E8: =IF(E6=0,0,IF(E6=1,Assumptions!$B$7,IF(E6=2,Assumptions!$B$8,Assumptions!$B$6))) | F8: =IF(F6=0,0,IF(F6=1,Assumptions!$B$7,IF(F6=2,Assumptions!$B$8,Assumptions!$B$6))) | G8: =IF(G6=0,0,IF(G6=1,Assumptions!$B$7,IF(G6=2,Assumptions!$B$8,Assumptions!$B$6))) | H8: =IF(H6=0,0,IF(H6=1,Assumptions!$B$7,IF(H6=2,Assumptions!$B$8,Assumptions!$B$6))) | I8: =IF(I6=0,0,IF(I6=1,Assumptions!$B$7,IF(I6=2,Assumptions!$B$8,Assumptions!$B$6))) | ... X8: =IF(X6=0,0,IF(X6=1,Assumptions!$B$7,IF(X6=2,Assumptions!$B$8,Assumptions!$B$6)))
A9: Discount factor | B9: =1/(1+Assumptions!$B$10)^B4 | C9: =1/(1+Assumptions!$B$10)^C4 | D9: =1/(1+Assumptions!$B$10)^D4 | E9: =1/(1+Assumptions!$B$10)^E4 | F9: =1/(1+Assumptions!$B$10)^F4 | G9: =1/(1+Assumptions!$B$10)^G4 | H9: =1/(1+Assumptions!$B$10)^H4 | I9: =1/(1+Assumptions!$B$10)^I4 | ... X9: =1/(1+Assumptions!$B$10)^X4
A10: Capital spend (escalated) | B10: =CAPEX!$F$23*B7*(1+Assumptions!$B$14)^(B4-1) | C10: =CAPEX!$F$23*C7*(1+Assumptions!$B$14)^(C4-1) | D10: =CAPEX!$F$23*D7*(1+Assumptions!$B$14)^(D4-1) | E10: =CAPEX!$F$23*E7*(1+Assumptions!$B$14)^(E4-1) | F10: =CAPEX!$F$23*F7*(1+Assumptions!$B$14)^(F4-1) | G10: =CAPEX!$F$23*G7*(1+Assumptions!$B$14)^(G4-1) | H10: =CAPEX!$F$23*H7*(1+Assumptions!$B$14)^(H4-1) | I10: =CAPEX!$F$23*I7*(1+Assumptions!$B$14)^(I4-1) | ... X10: =CAPEX!$F$23*X7*(1+Assumptions!$B$14)^(X4-1)
A11: Utilities | B11: =IF(B6=0,0,OPEX!$D$10*B8/Assumptions!$B$6*(1+Assumptions!$B$18)^MAX(0,B6-1)) | C11: =IF(C6=0,0,OPEX!$D$10*C8/Assumptions!$B$6*(1+Assumptions!$B$18)^MAX(0,C6-1)) | D11: =IF(D6=0,0,OPEX!$D$10*D8/Assumptions!$B$6*(1+Assumptions!$B$18)^MAX(0,D6-1)) | E11: =IF(E6=0,0,OPEX!$D$10*E8/Assumptions!$B$6*(1+Assumptions!$B$18)^MAX(0,E6-1)) | F11: =IF(F6=0,0,OPEX!$D$10*F8/Assumptions!$B$6*(1+Assumptions!$B$18)^MAX(0,F6-1)) | G11: =IF(G6=0,0,OPEX!$D$10*G8/Assumptions!$B$6*(1+Assumptions!$B$18)^MAX(0,G6-1)) | H11: =IF(H6=0,0,OPEX!$D$10*H8/Assumptions!$B$6*(1+Assumptions!$B$18)^MAX(0,H6-1)) | I11: =IF(I6=0,0,OPEX!$D$10*I8/Assumptions!$B$6*(1+Assumptions!$B$18)^MAX(0,I6-1)) | ... X11: =IF(X6=0,0,OPEX!$D$10*X8/Assumptions!$B$6*(1+Assumptions!$B$18)^MAX(0,X6-1))
A12: Raw materials | B12: =IF(B6=0,0,OPEX!$D$16*B8/Assumptions!$B$6*(1+Assumptions!$B$16)^MAX(0,B6-1)) | C12: =IF(C6=0,0,OPEX!$D$16*C8/Assumptions!$B$6*(1+Assumptions!$B$16)^MAX(0,C6-1)) | D12: =IF(D6=0,0,OPEX!$D$16*D8/Assumptions!$B$6*(1+Assumptions!$B$16)^MAX(0,D6-1)) | E12: =IF(E6=0,0,OPEX!$D$16*E8/Assumptions!$B$6*(1+Assumptions!$B$16)^MAX(0,E6-1)) | F12: =IF(F6=0,0,OPEX!$D$16*F8/Assumptions!$B$6*(1+Assumptions!$B$16)^MAX(0,F6-1)) | G12: =IF(G6=0,0,OPEX!$D$16*G8/Assumptions!$B$6*(1+Assumptions!$B$16)^MAX(0,G6-1)) | H12: =IF(H6=0,0,OPEX!$D$16*H8/Assumptions!$B$6*(1+Assumptions!$B$16)^MAX(0,H6-1)) | I12: =IF(I6=0,0,OPEX!$D$16*I8/Assumptions!$B$6*(1+Assumptions!$B$16)^MAX(0,I6-1)) | ... X12: =IF(X6=0,0,OPEX!$D$16*X8/Assumptions!$B$6*(1+Assumptions!$B$16)^MAX(0,X6-1))
A13: Labour, maintenance, charges, overhead | B13: =IF(B6=0,0,(OPEX!$D$18+OPEX!$D$19+OPEX!$D$21+OPEX!$D$22)*(1+Assumptions!$B$17)^MAX(0,B6-1)) | C13: =IF(C6=0,0,(OPEX!$D$18+OPEX!$D$19+OPEX!$D$21+OPEX!$D$22)*(1+Assumptions!$B$17)^MAX(0,C6-1)) | D13: =IF(D6=0,0,(OPEX!$D$18+OPEX!$D$19+OPEX!$D$21+OPEX!$D$22)*(1+Assumptions!$B$17)^MAX(0,D6-1)) | E13: =IF(E6=0,0,(OPEX!$D$18+OPEX!$D$19+OPEX!$D$21+OPEX!$D$22)*(1+Assumptions!$B$17)^MAX(0,E6-1)) | F13: =IF(F6=0,0,(OPEX!$D$18+OPEX!$D$19+OPEX!$D$21+OPEX!$D$22)*(1+Assumptions!$B$17)^MAX(0,F6-1)) | G13: =IF(G6=0,0,(OPEX!$D$18+OPEX!$D$19+OPEX!$D$21+OPEX!$D$22)*(1+Assumptions!$B$17)^MAX(0,G6-1)) | H13: =IF(H6=0,0,(OPEX!$D$18+OPEX!$D$19+OPEX!$D$21+OPEX!$D$22)*(1+Assumptions!$B$17)^MAX(0,H6-1)) | I13: =IF(I6=0,0,(OPEX!$D$18+OPEX!$D$19+OPEX!$D$21+OPEX!$D$22)*(1+Assumptions!$B$17)^MAX(0,I6-1)) | ... X13: =IF(X6=0,0,(OPEX!$D$18+OPEX!$D$19+OPEX!$D$21+OPEX!$D$22)*(1+Assumptions!$B$17)^MAX(0,X6-1))
A14: General & administrative | B14: =IF(B6=0,0,OPEX!$D$23*(1+Assumptions!$B$19)^MAX(0,B6-1)) | C14: =IF(C6=0,0,OPEX!$D$23*(1+Assumptions!$B$19)^MAX(0,C6-1)) | D14: =IF(D6=0,0,OPEX!$D$23*(1+Assumptions!$B$19)^MAX(0,D6-1)) | E14: =IF(E6=0,0,OPEX!$D$23*(1+Assumptions!$B$19)^MAX(0,E6-1)) | F14: =IF(F6=0,0,OPEX!$D$23*(1+Assumptions!$B$19)^MAX(0,F6-1)) | G14: =IF(G6=0,0,OPEX!$D$23*(1+Assumptions!$B$19)^MAX(0,G6-1)) | H14: =IF(H6=0,0,OPEX!$D$23*(1+Assumptions!$B$19)^MAX(0,H6-1)) | I14: =IF(I6=0,0,OPEX!$D$23*(1+Assumptions!$B$19)^MAX(0,I6-1)) | ... X14: =IF(X6=0,0,OPEX!$D$23*(1+Assumptions!$B$19)^MAX(0,X6-1))
A15: By-product credits | B15: =IF(B6=0,0,OPEX!$D$29*B8/Assumptions!$B$6*(1+Assumptions!$B$15)^MAX(0,B6-1)) | C15: =IF(C6=0,0,OPEX!$D$29*C8/Assumptions!$B$6*(1+Assumptions!$B$15)^MAX(0,C6-1)) | D15: =IF(D6=0,0,OPEX!$D$29*D8/Assumptions!$B$6*(1+Assumptions!$B$15)^MAX(0,D6-1)) | E15: =IF(E6=0,0,OPEX!$D$29*E8/Assumptions!$B$6*(1+Assumptions!$B$15)^MAX(0,E6-1)) | F15: =IF(F6=0,0,OPEX!$D$29*F8/Assumptions!$B$6*(1+Assumptions!$B$15)^MAX(0,F6-1)) | G15: =IF(G6=0,0,OPEX!$D$29*G8/Assumptions!$B$6*(1+Assumptions!$B$15)^MAX(0,G6-1)) | H15: =IF(H6=0,0,OPEX!$D$29*H8/Assumptions!$B$6*(1+Assumptions!$B$15)^MAX(0,H6-1)) | I15: =IF(I6=0,0,OPEX!$D$29*I8/Assumptions!$B$6*(1+Assumptions!$B$15)^MAX(0,I6-1)) | ... X15: =IF(X6=0,0,OPEX!$D$29*X8/Assumptions!$B$6*(1+Assumptions!$B$15)^MAX(0,X6-1))
A16: Net cost | B16: =B11+B12+B13+B14-B15 | C16: =C11+C12+C13+C14-C15 | D16: =D11+D12+D13+D14-D15 | E16: =E11+E12+E13+E14-E15 | F16: =F11+F12+F13+F14-F15 | G16: =G11+G12+G13+G14-G15 | H16: =H11+H12+H13+H14-H15 | I16: =I11+I12+I13+I14-I15 | ... X16: =X11+X12+X13+X14-X15
A17: Hydrogen (kg) | B17: =IF(B6=0,0,OPEX!$B$30*B8/Assumptions!$B$6) | C17: =IF(C6=0,0,OPEX!$B$30*C8/Assumptions!$B$6) | D17: =IF(D6=0,0,OPEX!$B$30*D8/Assumptions!$B$6) | E17: =IF(E6=0,0,OPEX!$B$30*E8/Assumptions!$B$6) | F17: =IF(F6=0,0,OPEX!$B$30*F8/Assumptions!$B$6) | G17: =IF(G6=0,0,OPEX!$B$30*G8/Assumptions!$B$6) | H17: =IF(H6=0,0,OPEX!$B$30*H8/Assumptions!$B$6) | I17: =IF(I6=0,0,OPEX!$B$30*I8/Assumptions!$B$6) | ... X17: =IF(X6=0,0,OPEX!$B$30*X8/Assumptions!$B$6)
A18: Hydrogen x product escalation | B18: =B17*(1+Assumptions!$B$15)^MAX(0,B6-1) | C18: =C17*(1+Assumptions!$B$15)^MAX(0,C6-1) | D18: =D17*(1+Assumptions!$B$15)^MAX(0,D6-1) | E18: =E17*(1+Assumptions!$B$15)^MAX(0,E6-1) | F18: =F17*(1+Assumptions!$B$15)^MAX(0,F6-1) | G18: =G17*(1+Assumptions!$B$15)^MAX(0,G6-1) | H18: =H17*(1+Assumptions!$B$15)^MAX(0,H6-1) | I18: =I17*(1+Assumptions!$B$15)^MAX(0,I6-1) | ... X18: =X17*(1+Assumptions!$B$15)^MAX(0,X6-1)
A19: PV net cost | B19: =B16*B9 | C19: =C16*C9 | D19: =D16*D9 | E19: =E16*E9 | F19: =F16*F9 | G19: =G16*G9 | H19: =H16*H9 | I19: =I16*I9 | ... X19: =X16*X9
A20: PV capital | B20: =B10*B9 | C20: =C10*C9 | D20: =D10*D9 | E20: =E10*E9 | F20: =F10*F9 | G20: =G10*G9 | H20: =H10*H9 | I20: =I10*I9 | ... X20: =X10*X9
A21: PV H2 x escalation | B21: =B18*B9 | C21: =C18*C9 | D21: =D18*D9 | E21: =E18*E9 | F21: =F18*F9 | G21: =G18*G9 | H21: =H18*H9 | I21: =I18*I9 | ... X21: =X18*X9
A23: Present value of capital | B23: =SUM(B20:X20)
A24: Present value of net operating cost | B24: =SUM(B19:X19)
A25: Present value of H2 x escalation (kg) | B25: =SUM(B21:X21)
A26: LCOH, first operating year (USD/kg H2), escalating at product rate | B26: =(B23+B24)/B25
A27: Capital share of LCOH | B27: =B23/(B23+B24)

Sheet LCA
A1: Life-cycle energy and GHG (gate-to-gate, steady-state year)
A2: NER = renewable energy out / fossil energy in, as defined in [1] section 4.5. Biogenic CO2 is reported but not counted.
A4: Item | B4: Value | C4: Unit | D4: Basis
A5: Energy
A6: Hydrogen produced | B6: =OPEX!$B$30 | C6: kg/yr | D6: From OPEX
A7: Energy output: hydrogen (LHV) | B7: =B6*Assumptions!$B$51/1000 | C7: GJ/yr | D7: H2 x LHV
A8: Electricity used | B8: =OPEX!$B$6 | C8: kWh/yr | D8: From OPEX
A9: Fossil primary energy for electricity | B9: =B8*0.0036*Assumptions!$B$71 | C9: GJ/yr | D9: kWh x 0.0036 x primary energy factor
A10: Natural gas used (all heating) | B10: =OPEX!$B$7+OPEX!$B$8 | C10: GJ/yr | D10: From OPEX
A11: Total fossil energy input | B11: =B9+B10 | C11: GJ/yr
A12: Net energy ratio (NER) | B12: =B7/B11 | C12: - | D12: > 1 means more renewable energy out than fossil energy in
A14: GHG emissions (kg CO2e/yr)
A15: Electricity | B15: =B8*Assumptions!$B$70 | C15: kg CO2e/yr | D15: kWh x grid factor
A16: Natural gas (combustion + upstream) | B16: =B10*(Assumptions!$B$72+Assumptions!$B$73) | C16: kg CO2e/yr | D16: GJ x (56.1 + upstream)
A17: Carbon stored in solid product (as CO2) | B17: =OPEX!$B$27*1000*44/12 | C17: kg CO2/yr | D17: Carbon t/yr x 1000 x 44/12 (biogenic carbon)
A18: Credit for stored carbon (applied if switch = 1) | B18: =-B17*Assumptions!$B$74 | C18: kg CO2e/yr | D18: Switch on Assumptions
A19: Net GHG | B19: =B15+B16+B18 | C19: kg CO2e/yr
A20: GHG intensity | B20: =B19/B6 | C20: kg CO2e/kg H2
A21: GHG intensity without carbon credit | B21: =(B15+B16)/B6 | C21: kg CO2e/kg H2
A22: GHG intensity with carbon credit | B22: =(B15+B16-B17)/B6 | C22: kg CO2e/kg H2 | D22: If the carbon is permanently stored
A24: Biogenic flows (information only, not counted)
A25: CO2 in membrane permeate (vented or captured) | B25: =Process_Data!$B$15*Process_Data!$B$16*44.01*OPEX!$B$4/1000 | C25: t/yr | D25: Biogenic CO2 from the biogas
A26: CH4 slip in permeate | B26: =Process_Data!$B$15*Process_Data!$B$17*16.043*OPEX!$B$4/1000 | C26: t/yr | D26: Must be flared or used; CH4 is a strong GHG if vented
A27: CO in pyrolysis product | B27: =Process_Data!$B$22*28.01*OPEX!$B$4/1000 | C27: t/yr | D27: Biogenic; becomes CO2 when burned
